<?xml version="1.0" encoding="utf-8"?>
<robot name="archer_d6y">

    <link name="base_link">
        <inertial>
            <origin xyz="-0.001 0 0.322" rpy="0 0 0" />
            <mass value="0.687" />
            <inertia ixx="0.0005" iyy="0.0005" izz="0.0007" ixy="0" ixz="0" iyz="0" />
        </inertial>
        <visual>
            <origin xyz="0 0 0" rpy="0 0 0" />
            <geometry>
                <mesh filename="package://xpkg_urdf_archer_d6y/meshes/base_link.STL" />
            </geometry>
            <material name="">
                <color rgba="1 1 1 1" />
            </material>
        </visual>
        <collision>
            <origin xyz="0 0 0" rpy="0 0 0" />
            <geometry>
                <mesh filename="package://xpkg_urdf_archer_d6y/meshes/base_link.STL" />
            </geometry>
        </collision>
    </link>

    <link name="link_1">
        <inertial>
            <origin xyz="0.008 -0.0023 0.0213" rpy="0 0 0" />
            <mass value="0.2154" />
            <inertia ixx="0.0003" iyy="0.0002" izz="0.0003" ixy="0" ixz="0" iyz="0"/>
        </inertial>
        <visual>
            <origin xyz="0 0 0" rpy="0 0 0" />
            <geometry>
                <mesh filename="package://xpkg_urdf_archer_d6y/meshes/link_1.STL" />
            </geometry>
            <material name="">
                <color rgba="1 1 1 1" />
            </material>
        </visual>
        <collision>
            <origin xyz="0 0 0" rpy="0 0 0" />
            <geometry>
                <mesh filename="package://xpkg_urdf_archer_d6y/meshes/link_1.STL" />
            </geometry>
        </collision>
    </link>
    <joint name="joint_1" type="revolute">
        <origin xyz="0 0 0.0665" rpy="0 0 0" />
        <parent link="base_link" />
        <child link="link_1" />
        <axis xyz="0 0 1" />
        <limit lower="-2.61" upper="3.14" effort="6" velocity="6" />
    </joint>

    <link name="link_2">
        <inertial>
            <origin xyz="0.0001 -0.0028 0.1317" rpy="0 0 0" />
            <mass value="1.3123" />
            <inertia ixx="0.018" iyy="0.0177" izz="0.0007" ixy="0" ixz="0" iyz="0.0007" />
        </inertial>
        <visual>
            <origin xyz="0 0 0" rpy="0 0 0" />
            <geometry>
                <mesh filename="package://xpkg_urdf_archer_d6y/meshes/link_2.STL" />
            </geometry>
            <material name="">
                <color rgba="1 1 1 1" />
            </material>
        </visual>
        <collision>
            <origin xyz="0 0 0" rpy="0 0 0" />
            <geometry>
                <mesh filename="package://xpkg_urdf_archer_d6y/meshes/link_2.STL" />
            </geometry>
        </collision>
    </link>
    <joint name="joint_2" type="revolute">
        <origin xyz="0.02 0 0.045" rpy="0 0 0" />
        <parent link="link_1" />
        <child link="link_2" />
        <axis xyz="0 1 0" />
        <limit lower="-1.57" upper="2.09" effort="6" velocity="6" />
    </joint>

    <link name="link_3">
        <inertial>
            <origin xyz="-0.051 0.0008 0.1447" rpy="0 0 0" />
            <mass value="1.1083" />
            <inertia ixx="0.0114" iyy="0.0112" izz="0.0016" ixy="-0.0001" ixz="0.0014" iyz="0.0006" />
        </inertial>
        <visual>
            <origin xyz="0 0 0" rpy="0 0 0" />
            <geometry>
                <mesh filename="package://xpkg_urdf_archer_d6y/meshes/link_3.STL" />
            </geometry>
            <material name="">
                <color rgba="1 1 1 1" />
            </material>
        </visual>
        <collision>
            <origin xyz="0 0 0" rpy="0 0 0" />
            <geometry>
                <mesh filename="package://xpkg_urdf_archer_d6y/meshes/link_3.STL" />
            </geometry>
        </collision>
    </link>
    <joint name="joint_3" type="revolute">
        <origin xyz="0 0 0.264" rpy="0 0 0" />
        <parent link="link_2" />
        <child link="link_3" />
        <axis xyz="0 1 0" />
        <limit lower="0" upper="3.14" effort="6" velocity="6" />
    </joint>

    <link name="link_4">
        <inertial>
            <origin xyz="-0.0597 -0.001 0.0572" rpy="0 0 0" />
            <mass value="0.5398" />
            <inertia ixx="0.0008" iyy="0.001" izz="0.0008" ixy="0" ixz="0.0003" iyz="0" />
        </inertial>
        <visual>
            <origin xyz="0 0 0" rpy="0 0 0" />
            <geometry>
                <mesh filename="package://xpkg_urdf_archer_d6y/meshes/link_4.STL" />
            </geometry>
            <material name="">
                <color rgba="1 1 1 1" />
            </material>
        </visual>
        <collision>
            <origin xyz="0 0 0" rpy="0 0 0" />
            <geometry>
                <mesh filename="package://xpkg_urdf_archer_d6y/meshes/link_4.STL" />
            </geometry>
        </collision>
    </link>
    <joint name="joint_4" type="revolute">
        <origin xyz="-0.06 0 0.245" rpy="0 0 0" />
        <parent link="link_3" />
        <child link="link_4" />
        <axis xyz="0 1 0" />
        <limit lower="-1.57" upper="1.57" effort="6" velocity="6" />
    </joint>

    <link name="link_5">
        <inertial>
            <origin xyz="0.0292 0.0001 -0.0107" rpy="0 0 0" />
            <mass value="0.3984" />
            <inertia ixx="0.0002" iyy="0.0003" izz="0.0002" ixy="0" ixz="0" iyz="0" />
        </inertial>
        <visual>
            <origin xyz="0 0 0" rpy="0 0 0" />
            <geometry>
                <mesh filename="package://xpkg_urdf_archer_d6y/meshes/link_5.STL" />
            </geometry>
            <material name="">
                <color rgba="1 1 1 1" />
            </material>
        </visual>
        <collision>
            <origin xyz="0 0 0" rpy="0 0 0" />
            <geometry>
                <mesh filename="package://xpkg_urdf_archer_d6y/meshes/link_5.STL" />
            </geometry>
        </collision>
    </link>
    <joint name="joint_5" type="revolute">
        <origin xyz="-0.0553 0 0.070" rpy="0 0 0" />
        <parent link="link_4" />
        <child link="link_5" />
        <axis xyz="-1 0 0" />
        <limit lower="-1.57" upper="1.57" effort="6" velocity="6" />
    </joint>

    <link name="link_6">
        <inertial>
            <origin xyz="-0.009 0.0001 0.059" rpy="0 0 0" />
            <mass value="0.8192" />
            <inertia ixx="0.0012" ixy="0" ixz="-0.0002" iyy="0.025" iyz="0" izz="0.0018" />
        </inertial>
        <visual>
            <origin xyz="0 0 0" rpy="0 0 0" />
            <geometry>
                <mesh filename="package://xpkg_urdf_archer_d6y/meshes/link_6.STL" />
            </geometry>
            <material name="">
                <color rgba="1 1 1 1" />
            </material>
        </visual>
        <collision>
            <origin xyz="0 0 0" rpy="0 0 0" />
            <geometry>
                <mesh filename="package://xpkg_urdf_archer_d6y/meshes/link_6.STL" />
            </geometry>
        </collision>
    </link>
    <joint name="joint_6" type="revolute">
        <origin xyz="0.0553 0 0.029" rpy="0 0 0" />
        <parent link="link_5" />
        <child link="link_6" />
        <axis xyz="0 0 1" />
        <limit lower="-2.96" upper="2.96" effort="6" velocity="6" />
    </joint>

</robot>