<?xml version="1.0" encoding="utf-8"?>
<robot name="archer_y6">

    <link name="base_link">
        <inertial>
            <origin xyz="-0.001 0 0.031" rpy="0 0 0" />
            <mass value="0.748" />
            <inertia ixx="0.0006" iyy="0.0007" izz="0.0008" ixy="0" ixz="0" iyz="0" />
        </inertial>
        <visual>
            <origin xyz="0 0 0" rpy="0 0 0" />
            <geometry>
                <mesh filename="package://xpkg_urdf_archer_y6/meshes/base_link.STL" />
            </geometry>
            <material name="">
                <color rgba="1 1 1 1" />
            </material>
        </visual>
        <collision>
            <origin xyz="0 0 0" rpy="0 0 0" />
            <geometry>
                <mesh filename="package://xpkg_urdf_archer_y6/meshes/base_link.STL" />
            </geometry>
        </collision>
    </link>

    <link name="link_1">
        <inertial>
            <origin xyz="0.006 -0.0013 0.0209" rpy="0 0 0" />
            <mass value="0.2289" />
            <inertia ixx="0.0004" iyy="0.0002" izz="0.0004" ixy="0" ixz="0" iyz="0"/>
        </inertial>
        <visual>
            <origin xyz="0 0 0" rpy="0 0 0" />
            <geometry>
                <mesh filename="package://xpkg_urdf_archer_y6/meshes/link_1.STL" />
            </geometry>
            <material name="">
                <color rgba="1 1 1 1" />
            </material>
        </visual>
        <collision>
            <origin xyz="0 0 0" rpy="0 0 0" />
            <geometry>
                <mesh filename="package://xpkg_urdf_archer_y6/meshes/link_1.STL" />
            </geometry>
        </collision>
    </link>
    <joint name="joint_1" type="revolute">
        <origin xyz="0 0 0.06655" rpy="0 0 0" />
        <parent link="base_link" />
        <child link="link_1" />
        <axis xyz="0 0 1" />
        <limit lower="-2.91" upper="2.91" effort="6" velocity="6" />
    </joint>

    <link name="link_2">
        <inertial>
            <origin xyz="0.0001 -0.0013 0.1301" rpy="0 0 0" />
            <mass value="1.5141" />
            <inertia ixx="0.021" iyy="0.0208" izz="0.0011" ixy="0" ixz="0" iyz="-0.0001" />
        </inertial>
        <visual>
            <origin xyz="0 0 0" rpy="0 0 0" />
            <geometry>
                <mesh filename="package://xpkg_urdf_archer_y6/meshes/link_2.STL" />
            </geometry>
            <material name="">
                <color rgba="1 1 1 1" />
            </material>
        </visual>
        <collision>
            <origin xyz="0 0 0" rpy="0 0 0" />
            <geometry>
                <mesh filename="package://xpkg_urdf_archer_y6/meshes/link_2.STL" />
            </geometry>
        </collision>
    </link>
    <joint name="joint_2" type="revolute">
        <origin xyz="0.02 0 0.045" rpy="0 0 0" />
        <parent link="link_1" />
        <child link="link_2" />
        <axis xyz="0 1 0" />
        <limit lower="-1.57" upper="2.09" effort="6" velocity="6" />
    </joint>

    <link name="link_3">
        <inertial>
            <origin xyz="-0.054 -0.0015 0.1603" rpy="0 0 0" />
            <mass value="1.2023" />
            <inertia ixx="0.011" iyy="0.0106" izz="0.0016" ixy="0" ixz="0.0011" iyz="0" />
        </inertial>
        <visual>
            <origin xyz="0 0 0" rpy="0 0 0" />
            <geometry>
                <mesh filename="package://xpkg_urdf_archer_y6/meshes/link_3.STL" />
            </geometry>
            <material name="">
                <color rgba="1 1 1 1" />
            </material>
        </visual>
        <collision>
            <origin xyz="0 0 0" rpy="0 0 0" />
            <geometry>
                <mesh filename="package://xpkg_urdf_archer_y6/meshes/link_3.STL" />
            </geometry>
        </collision>
    </link>
    <joint name="joint_3" type="revolute">
        <origin xyz="0 0 0.264" rpy="0 0 0" />
        <parent link="link_2" />
        <child link="link_3" />
        <axis xyz="0 1 0" />
        <limit lower="0" upper="3.14" effort="6" velocity="6" />
    </joint>

    <link name="link_4">
        <inertial>
            <origin xyz="-0.0580 -0.002 0.0558" rpy="0 0 0" />
            <mass value="0.6233" />
            <inertia ixx="0.0011" iyy="0.0012" izz="0.0011" ixy="0" ixz="0.0004" iyz="0" />
        </inertial>
        <visual>
            <origin xyz="0 0 0" rpy="0 0 0" />
            <geometry>
                <mesh filename="package://xpkg_urdf_archer_y6/meshes/link_4.STL" />
            </geometry>
            <material name="">
                <color rgba="1 1 1 1" />
            </material>
        </visual>
        <collision>
            <origin xyz="0 0 0" rpy="0 0 0" />
            <geometry>
                <mesh filename="package://xpkg_urdf_archer_y6/meshes/link_4.STL" />
            </geometry>
        </collision>
    </link>
    <joint name="joint_4" type="revolute">
        <origin xyz="-0.06 0 0.245" rpy="0 0 0" />
        <parent link="link_3" />
        <child link="link_4" />
        <axis xyz="0 1 0" />
        <limit lower="-1.57" upper="1.57" effort="6" velocity="6" />
    </joint>

    <link name="link_5">
        <inertial>
            <origin xyz="0.0512 0 0.0026" rpy="0 0 0" />
            <mass value="0.4173" />
            <inertia ixx="0.0002" iyy="0.0003" izz="0.0003" ixy="0" ixz="0" iyz="0" />
        </inertial>
        <visual>
            <origin xyz="0 0 0" rpy="0 0 0" />
            <geometry>
                <mesh filename="package://xpkg_urdf_archer_y6/meshes/link_5.STL" />
            </geometry>
            <material name="">
                <color rgba="1 1 1 1" />
            </material>
        </visual>
        <collision>
            <origin xyz="0 0 0" rpy="0 0 0" />
            <geometry>
                <mesh filename="package://xpkg_urdf_archer_y6/meshes/link_5.STL" />
            </geometry>
        </collision>
    </link>
    <joint name="joint_5" type="revolute">
        <origin xyz="-0.0553 0 0.0702" rpy="0 0 0" />
        <parent link="link_4" />
        <child link="link_5" />
        <axis xyz="-1 0 0" />
        <limit lower="-1.57" upper="1.57" effort="6" velocity="6" />
    </joint>

    <link name="link_6">
        <inertial>
            <origin xyz="-0.009 0.0001 0.059" rpy="0 0 0" />
            <mass value="0.8192" />
            <inertia ixx="0.0012" ixy="0" ixz="-0.0002" iyy="0.025" iyz="0" izz="0.0018" />
        </inertial>
        <visual>
            <origin xyz="0 0 0" rpy="0 0 0" />
            <geometry>
                <mesh filename="package://xpkg_urdf_archer_y6/meshes/link_6.STL" />
            </geometry>
            <material name="">
                <color rgba="1 1 1 1" />
            </material>
        </visual>
        <collision>
            <origin xyz="0 0 0" rpy="0 0 0" />
            <geometry>
                <mesh filename="package://xpkg_urdf_archer_y6/meshes/link_6.STL" />
            </geometry>
        </collision>
    </link>
    <joint name="joint_6" type="revolute">
        <origin xyz="0.0552 0 0.02895" rpy="0 0 0" />
        <parent link="link_5" />
        <child link="link_6" />
        <axis xyz="0 0 1" />
        <limit lower="-2.96" upper="2.96" effort="6" velocity="6" />
    </joint>

</robot>