<mujocoinclude>
    <body name="right_base_link">
        <inertial pos="-0.000151 -0.0000031 0.04926" mass="0.8743" diaginertia="0.0013187 0.0013351 0.0010065"/>
        <geom type="mesh" rgba="1 1 1 1" mesh="arm_base_link"/>

        <!-- link 1 -->
        <body name="right_link_1" pos="0 0 0.09505">
            <inertial pos="0.00672 -0.00276 0.02394" mass="0.2545" diaginertia="0.000367 0.000228 0.000324"/>
            <joint name="right_joint_1" pos="0 0 0" axis="0 0 1" range="-2.7 2.7" limited="true" armature="0.01" damping="0.1" frictionloss="0.5"/>
            <geom type="mesh" rgba="0.92549 0.92549 0.92549 1" mesh="arm_link_1"/>

            <!-- link 2 -->
            <body name="right_link_2" pos="0.02 0 0.05">
                <inertial pos="-0.00065 0.00051 0.13439" mass="1.2827" diaginertia="0.01970 0.01950 0.000713"/>
                <joint name="right_joint_2" pos="0 0 0" axis="0 1 0" range="-1.57 2.094" limited="true" armature="0.01" damping="0.1" frictionloss="0.5"/>
                <geom type="mesh" rgba="1 1 1 1" mesh="arm_link_2"/>

                <!-- link 3 -->
                <body name="right_link_3" pos="0 0 0.27">
                    <inertial pos="-0.05669 -0.00288 0.15456" mass="0.9359" diaginertia="0.00984 0.00991 0.00105"/>
                    <joint name="right_joint_3" pos="0 0 0" axis="0 1 0" range="0 3.14159" limited="true" armature="0.01" damping="0.1" frictionloss="0.5"/>
                    <geom type="mesh" rgba="1 1 1 1" mesh="arm_link_3"/>

                    <!-- link 4 -->
                    <body name="right_link_4" pos="-0.065 0 0.25">
                        <inertial pos="-0.05184 -0.00200 0.04855" mass="0.5506" diaginertia="0.000756 0.000982 0.000799"/>
                        <joint name="right_joint_4" pos="0 0 0" axis="0 1 0" range="-1.56 1.56" limited="true" armature="0.01" damping="0.02" frictionloss="0.1"/>
                        <geom type="mesh" rgba="0.792157 0.792157 0.792157 1" mesh="arm_link_4"/>

                        <!-- link 5 -->
                        <body name="right_link_5" pos="-0.047 0 0.065">
                            <inertial pos="0.04236 -0.0000033 0.00771" mass="0.4105" diaginertia="0.000186 0.000256 0.000237"/>
                            <joint name="right_joint_5" pos="0 0 0" axis="-1 0 0" range="-1.56 1.56" limited="true" armature="0.01" damping="0.02" frictionloss="0.1"/>
                            <geom type="mesh" rgba="0.898039 0.917647 0.929412 1" mesh="arm_link_5"/>

                            <!-- link 6 (wrist rotation) -->
                            <body name="right_link_6" pos="0.047 0 0.034">
                                <inertial pos="-0.00049 0 0.00344" mass="0.0076" diaginertia="0.00000089 0.00000065 0.00000143"/>
                                <joint name="right_joint_6" pos="0 0 0" axis="0 0 1" range="-2.96 2.96" limited="true" armature="0.01" damping="0.02" frictionloss="0.1"/>
                                <geom type="mesh" rgba="0.898039 0.917647 0.929412 1" mesh="arm_link_6"/>

                                <!-- Gripper base frame = link_6 (identity). Kept un-rotated so the wrist
                                     camera + ee_frame (calibrated to link_6) are unaffected. The Tianyi 总装
                                     gripper body + claws hang off a child mount rotated rpy(0,0,-90deg). -->
                                <body name="right_gripper_base_link" pos="0 0 0" quat="1 0 0 0">
                                    <inertial pos="0 0 0.02" mass="0.0001" diaginertia="1e-7 1e-7 1e-7"/>

                                    <!-- Wrist camera + visual mesh — derived from real hand-eye calibration
                                         (hand_eye_calibration/results/dual/right_hand.json, T_cam2gripper).
                                         See robot_left.xml for the frame conventions. -->
                                    <geom pos="-0.0665073 -0.0036781 0.0711148" quat="0.5794969 -0.3468796 0.3910128 0.6252735"
                                          type="mesh" rgba="0.667 0.698 0.769 1" mesh="camera_link"/>
                                    <camera name="right_end_camera"
                                            pos="-0.0670463 0.0288147 0.0715402"
                                            quat="0.1479058 0.6974347 -0.6840006 -0.1544408"
                                            fovy="43.2"/>

                                    <!-- ee frame (TCP 0.187m along +Z, measured) -->
                                    <body name="right_ee_frame" pos="0 0 0.187" quat="1 0 0 0">
                                        <geom type="cylinder" size="0.002 0.01" pos="0.01 0.00 0.00" quat="0.7071068 0.0 0.7071068 0.0" rgba="1 0 0 1" contype="0" conaffinity="0" group="4"/>
                                        <geom type="cylinder" size="0.002 0.01" pos="0.00 0.01 0.00" quat="0.7071068 0.7071068 0.0 0.0" rgba="0 1 0 1" contype="0" conaffinity="0" group="4"/>
                                        <geom type="cylinder" size="0.002 0.01" pos="0.00 0.00 0.01" quat="1.0 0.0 0.0 0.0" rgba="0 0 1 1" contype="0" conaffinity="0" group="4"/>
                                    </body>

                                    <!-- Tianyi 总装 gripper: body (Link_1) + 2 claws. Mount = Rz(+90deg)
                                         about the wrist axis to match the soda-ui (three.js) render. MuJoCo
                                         renders meshes through their mesh_quat while three.js renders them
                                         as-is, so this +90deg aligns the sim gripper with the UI orientation.
                                         Claws axis 0 0 -1; right mimics left (multiplier -1, setting_dual.xml). -->
                                    <body name="right_gripper_mount" pos="0 0 0" quat="0.7071068 0 0 0.7071068">
                                        <inertial pos="0 0.00524 0.04602" mass="0.47163661" diaginertia="0.00032421 0.00032388 0.00022576"/>
                                        <geom type="mesh" rgba="1 1 1 1" mesh="gripper_base_link"/>

                                        <!-- left claw (driven) = Link_2 -->
                                        <body name="right_gripper_left_link_1" pos="-0.015 0.01475 0.07679888" quat="0.5 0.5 0.5 -0.5">
                                            <inertial pos="-0.04997 -0.03775 0.01429" mass="0.02806607" diaginertia="0.00000957 0.00002838 0.00003601"/>
                                            <joint name="right_gripper_left_joint_1" pos="0 0 0" axis="0 0 -1" range="0 0.9" limited="true" armature="0.01" damping="1.0" frictionloss="0.1"/>
                                            <geom type="mesh" rgba="1 1 1 1" mesh="gripper_L1"/>
                                        </body>

                                        <!-- right claw (mimics left, multiplier -1) = Link_3 -->
                                        <body name="right_gripper_right_link_1" pos="0.015 0.01475 0.07679888" quat="0.5 0.5 0.5 -0.5">
                                            <inertial pos="-0.04997 0.03775 0.01413" mass="0.02806607" diaginertia="0.00000957 0.00002838 0.00003601"/>
                                            <joint name="right_gripper_right_joint_1" pos="0 0 0" axis="0 0 -1" range="-0.9 0.9" limited="true" armature="0.01" damping="1.0" frictionloss="0.1"/>
                                            <geom type="mesh" rgba="1 1 1 1" mesh="gripper_L2"/>
                                        </body>
                                    </body>
                                </body>
                            </body>
                        </body>
                    </body>
                </body>
            </body>
        </body>
    </body>
</mujocoinclude>
