<mujocoinclude>
    <body name="left_base_link">
        <inertial pos="-0.000151 -0.0000031 0.04926" mass="0.8743" diaginertia="0.0013187 0.0013351 0.0010065"/>
        <geom type="mesh" rgba="1 1 1 1" mesh="arm_base_link"/>

        <!-- link 1 -->
        <body name="left_link_1" pos="0 0 0.09505">
            <inertial pos="0.00672 -0.00276 0.02394" mass="0.2545" diaginertia="0.000367 0.000228 0.000324"/>
            <joint name="left_joint_1" pos="0 0 0" axis="0 0 1" range="-2.86 2.86" limited="true" armature="0.01" damping="0.1" frictionloss="0.5"/>
            <geom type="mesh" rgba="0.92549 0.92549 0.92549 1" mesh="arm_link_1"/>

            <!-- link 2 -->
            <body name="left_link_2" pos="0.02 0 0.05">
                <inertial pos="-0.00065 0.00051 0.13439" mass="1.2827" diaginertia="0.01970 0.01950 0.000713"/>
                <joint name="left_joint_2" pos="0 0 0" axis="0 1 0" range="-1.57 2.09" limited="true" armature="0.01" damping="0.1" frictionloss="0.5"/>
                <geom type="mesh" rgba="1 1 1 1" mesh="arm_link_2"/>

                <!-- link 3 -->
                <body name="left_link_3" pos="0 0 0.27">
                    <inertial pos="-0.05669 -0.00288 0.15456" mass="0.9359" diaginertia="0.00984 0.00991 0.00105"/>
                    <joint name="left_joint_3" pos="0 0 0" axis="0 1 0" range="0 3.14" limited="true" armature="0.01" damping="0.1" frictionloss="0.5"/>
                    <geom type="mesh" rgba="1 1 1 1" mesh="arm_link_3"/>

                    <!-- link 4 -->
                    <body name="left_link_4" pos="-0.065 0 0.25">
                        <inertial pos="-0.05184 -0.00200 0.04855" mass="0.5506" diaginertia="0.000756 0.000982 0.000799"/>
                        <joint name="left_joint_4" pos="0 0 0" axis="0 1 0" range="-1.57 1.57" limited="true" armature="0.01" damping="0.02" frictionloss="0.1"/>
                        <geom type="mesh" rgba="0.792157 0.792157 0.792157 1" mesh="arm_link_4"/>

                        <!-- link 5 -->
                        <body name="left_link_5" pos="-0.047 0 0.065">
                            <inertial pos="0.04236 -0.0000033 0.00771" mass="0.4105" diaginertia="0.000186 0.000256 0.000237"/>
                            <joint name="left_joint_5" pos="0 0 0" axis="-1 0 0" range="-1.54 1.54" limited="true" armature="0.01" damping="0.02" frictionloss="0.1"/>
                            <geom type="mesh" rgba="0.898039 0.917647 0.929412 1" mesh="arm_link_5"/>

                            <!-- link 6 (wrist rotation) -->
                            <body name="left_link_6" pos="0.047 0 0.034">
                                <inertial pos="-0.00049 0 0.00344" mass="0.0076" diaginertia="0.00000089 0.00000065 0.00000143"/>
                                <joint name="left_joint_6" pos="0 0 0" axis="0 0 1" range="-2.79 2.79" limited="true" armature="0.01" damping="0.02" frictionloss="0.1"/>
                                <geom type="mesh" rgba="0.898039 0.917647 0.929412 1" mesh="arm_link_6"/>

                                <!-- gripper base link (GR100 lobster claw) - identity rotation:
                                     gr100 claws lie along its own +Z, which already aligns with link_6 +Z (wrist axis forward) -->
                                <body name="left_gripper_base_link" pos="0 0 0" quat="1 0 0 0">
                                    <inertial pos="-0.00386 0 0.04222" mass="0.4716" diaginertia="0.000324 0.000324 0.000226"/>
                                    <geom type="mesh" rgba="1 1 1 1" mesh="gripper_base_link"/>

                                    <!-- Wrist camera + visual mesh — GENERATED by
                                         tools/sync_sim_cameras_from_calib.py from the hand-eye calibration
                                         (left_hand.json, T_cam2gripper). Do not hand-edit pos/quat — re-run the tool.
                                         <camera> = calibrated RGB optical pose (OpenCV optical -> MuJoCo x=right,
                                                    y=-down, z=-view); the sim renders RGB+depth from here so it
                                                    matches the real color camera. fovy 43.2° = 1920x1080 intrinsics.
                                         mesh     = D435i body. Its principal axes are aligned to the optical frame
                                                    (long bar -> baseline, lens -> view), and it is placed at
                                                    optical + 0.0325 m along the baseline (the fixed RGB->geometric-
                                                    center device offset, realsense2_description), so the body sits
                                                    at the true device center (~on the gripper centerline) while the
                                                    RGB optical center stays at its real left-offset position. -->
                                    <geom pos="-0.0629626 0.0013266 0.0677086" quat="0.5871090 -0.3363830 0.3995498 0.6184735"
                                          type="mesh" rgba="0.667 0.698 0.769 1" mesh="camera_link"/>
                                    <camera name="left_end_camera"
                                            pos="-0.0624713 0.0338194 0.0681815"
                                            quat="-0.1491669 -0.6857044 0.6938724 0.1615541"
                                            fovy="43.2"/>

                                    <!-- ee frame (TCP 0.187m along +Z, measured) -->
                                    <body name="left_ee_frame" pos="0 0 0.187" quat="1 0 0 0">
                                        <geom type="cylinder" size="0.002 0.01" pos="0.01 0.00 0.00" quat="0.7071068 0.0 0.7071068 0.0" rgba="1 0 0 1" contype="0" conaffinity="0" group="4"/>
                                        <geom type="cylinder" size="0.002 0.01" pos="0.00 0.01 0.00" quat="0.7071068 0.7071068 0.0 0.0" rgba="0 1 0 1" contype="0" conaffinity="0" group="4"/>
                                        <geom type="cylinder" size="0.002 0.01" pos="0.00 0.00 0.01" quat="1.0 0.0 0.0 0.0" rgba="0 0 1 1" contype="0" conaffinity="0" group="4"/>
                                    </body>

                                    <!-- left claw L1 (driven, axis=-X) -->
                                    <body name="left_gripper_left_link_1" pos="0 -0.015 0.076799">
                                        <inertial pos="0.01344 -0.02403 0.03494" mass="0.0281" diaginertia="0.0000229 0.0000184 0.0000063"/>
                                        <joint name="left_gripper_left_joint_1" pos="0 0 0" axis="-1 0 0" range="0 0.9" limited="true" armature="0.01" damping="1.0" frictionloss="0.1"/>
                                        <geom type="mesh" rgba="1 1 1 1" mesh="gripper_L1"/>
                                    </body>

                                    <!-- right claw L2 (mimics via equality, axis=+X) -->
                                    <body name="left_gripper_right_link_1" pos="0 0.015 0.076799">
                                        <inertial pos="0.01341 0.02402 0.03495" mass="0.0281" diaginertia="0.0000229 0.0000184 0.0000063"/>
                                        <joint name="left_gripper_right_joint_1" pos="0 0 0" axis="1 0 0" range="0 0.9" limited="true" armature="0.01" damping="1.0" frictionloss="0.1"/>
                                        <geom type="mesh" rgba="1 1 1 1" mesh="gripper_L2"/>
                                    </body>
                                </body>
                            </body>
                        </body>
                    </body>
                </body>
            </body>
        </body>
    </body>
</mujocoinclude>
