<mujoco model="firefly_y6 scene_table">
    <compiler angle="radian"/>
    <option integrator="implicitfast"/>
    <option timestep="1e-3"/>

    <statistic center="0.3 0 0.5" extent="0.8" meansize="0.05"/>

    <visual>
        <headlight diffuse="0.6 0.6 0.6" ambient="0.1 0.1 0.1" specular="0 0 0"/>
        <rgba haze="0.15 0.25 0.35 1"/>
        <global azimuth="120" elevation="-20"/>
        <map znear="0.001" zfar="50"/>
    </visual>

    <asset>
        <texture type="skybox" builtin="gradient" rgb1="0.3 0.5 0.7" rgb2="0 0 0" width="512" height="3072"/>
        <texture type="2d" name="groundplane" builtin="checker" mark="edge" rgb1="0.2 0.3 0.4" rgb2="0.1 0.2 0.3" markrgb="0.8 0.8 0.8" width="300" height="300"/>
        <material name="groundplane" texture="groundplane" texuniform="true" texrepeat="5 5" reflectance="0.2"/>
        <include file="assets/assets.xml"/>
    </asset>

    <worldbody>
        <light pos="0.0 0.0 1.5" directional="true"/>
        <geom name="floor" size="0.0 0.0 0.05" type="plane" material="groundplane"/>

        <body pos="0.0 0.0 0.25">
            <include file="robot.xml"/>
        </body>

        <body name="table" pos="0.5 0.0 0.3" quat="0.707107 0 0 0.707107">
            <geom mesh="table_link" pos="0 0 0" type="mesh" name="table" rgba="0.2 0.2 0.2 1"/>
        </body>
        <!-- apple, block, dog, kong, panda 暂时注释掉 -->
        <!--
        <body name="apple" pos="0.46 -0.14 0.5">
            <joint name="apple_joint" type="free" frictionloss="0.01"/>
            <inertial pos="0 0 0" mass="0.05" diaginertia="0.002 0.002 0.002"/>
            <geom condim="4" solimp="2 1 0.01" solref="0.01 1" friction="1 0.005 0.0001" pos="0 0 0" size="0.028" type="sphere" name="apple_body" rgba="0.86 0.08 0.10 1"/>
            <geom contype="0" conaffinity="0" pos="0 0 0.03" size="0.004 0.012" type="capsule" name="apple_stem" rgba="0.38 0.22 0.10 1"/>
            <geom contype="0" conaffinity="0" pos="0.01 0.0 0.035" euler="0 0.5 0" size="0.004 0.009" type="capsule" name="apple_leaf" rgba="0.12 0.62 0.20 1"/>
        </body>
        <body name="block" pos="0.52 -0.03 0.47">
            <joint name="block_joint" type="free" frictionloss="0.01"/>
            <inertial pos="0 0 0.015" mass="0.02" diaginertia="0.00001 0.00001 0.00001"/>
            <geom type="mesh" mesh="scanned_block_visual" material="scanned_block_mat"
                  contype="0" conaffinity="0" group="2" name="block_visual"/>
            <geom type="box" size="0.015 0.015 0.015" pos="0 0 0.015"
                  condim="4" solimp="2 1 0.01" solref="0.01 1" friction="1 0.005 0.0001"
                  group="3" rgba="0 0 0 0" name="block_collision"/>
        </body>
        <body name="dog" pos="0.46 0.07 0.47">
            <joint name="dog_joint" type="free" frictionloss="0.01"/>
            <inertial pos="0 0 0.025" mass="0.03" diaginertia="0.00002 0.00002 0.00002"/>
            <geom type="mesh" mesh="scanned_dog_visual" material="scanned_dog_mat"
                  contype="0" conaffinity="0" group="2" name="dog_visual"/>
            <geom type="box" size="0.017 0.024 0.025" pos="0 0 0.025"
                  condim="4" solimp="2 1 0.01" solref="0.01 1" friction="1 0.005 0.0001"
                  group="3" rgba="0 0 0 0" name="dog_collision"/>
        </body>
        <body name="kong" pos="0.56 0.14 0.47">
            <joint name="kong_joint" type="free" frictionloss="0.01"/>
            <inertial pos="0 0 0.036" mass="0.04" diaginertia="0.00002 0.00002 0.00002"/>
            <geom type="mesh" mesh="scanned_kong_visual" material="scanned_kong_mat"
                  contype="0" conaffinity="0" group="2" name="kong_visual"/>
            <geom type="cylinder" size="0.022 0.036" pos="0 0 0.036"
                  condim="4" solimp="2 1 0.01" solref="0.01 1" friction="1.2 0.005 0.0001"
                  group="3" rgba="0 0 0 0" name="kong_collision"/>
        </body>
        <body name="panda" pos="0.56 -0.11 0.47">
            <joint name="panda_joint" type="free" frictionloss="0.01"/>
            <inertial pos="0 0 0.038" mass="0.05" diaginertia="0.00003 0.00003 0.00003"/>
            <geom type="mesh" mesh="scanned_panda_visual" material="scanned_panda_mat"
                  contype="0" conaffinity="0" group="2" name="panda_visual"/>
            <geom type="box" size="0.030 0.023 0.038" pos="0 0 0.038"
                  condim="4" solimp="2 1 0.01" solref="0.01 1" friction="1 0.005 0.0001"
                  group="3" rgba="0 0 0 0" name="panda_collision"/>
        </body>
        -->
        <!-- Scanned coffee mug with handle, scaled 60% (7.6x5.4x8.1cm) -->
        <!-- 放置在 PartNet table 中层搁板上，偏右侧（机械臂视角），略微伸出搁板一点 -->
        <body name="mug" pos="0.45 -0.018 0.6803">
            <joint name="mug_joint" type="free" frictionloss="0.01"/>
            <inertial pos="0 0 0.040" mass="0.12" diaginertia="0.00005 0.00005 0.00004"/>
            <geom type="mesh" mesh="scanned_mug_visual" material="scanned_mug_mat"
                  contype="0" conaffinity="0" group="2" name="mug_visual"/>
            <geom type="cylinder" size="0.027 0.040" pos="0 0 0.040"
                  condim="4" solimp="2 1 0.01" solref="0.01 1" friction="1 0.005 0.0001"
                  group="3" rgba="0 0 0 0" name="mug_collision"/>
        </body>
        <!-- PartNet-Mobility Table id=22508 (带抽屉小桌, 总缩放32.5%, 约0.39x0.39x0.42m) -->
        <!-- 放置在prop table桌面上: 桌面z≈0.47, 底部偏移0.22685(=0.349×0.65), body z=0.69685 -->
        <body name="table_22508" pos="0.58 -0.05 0.69685">
            <joint name="table_22508_free" type="free" frictionloss="0.1"/>
            <inertial pos="0 0 0" mass="6.591" diaginertia="0.1856465 0.1856465 0.1113879"/>
            <!-- link_1: 桌体，fixed joint quat=(0.5 0.5 -0.5 -0.5) 对应 rpy=(pi/2,0,-pi/2) -->
            <!-- 碰撞体尺寸为0.65x mesh(顶点)的一半，与assets.xml中scale="0.65"对应 -->
            <body name="table_22508_link1" quat="0.5 0.5 -0.5 -0.5">
                <geom type="mesh" mesh="t22508_body" material="t22508_wood"
                      contype="0" conaffinity="0" group="2" name="t22508_body_visual"/>
                <!-- 碰撞分三段，中间留出杯子空间 (link_1 Y轴 = 世界Z轴) -->
                <!-- 段1: 下部桌腿+框架  link_1 Y: -0.2275 ~ -0.0325  世界Z: 0.470~0.665 -->
                <geom type="box" size="0.1911 0.0975 0.1911" pos="0.0104 -0.130 0.0039"
                      condim="4" solimp="2 1 0.01" solref="0.01 1" friction="1 0.005 0.0001"
                      group="3" rgba="0 0 0 0" name="t22508_legs_col"/>
                <!-- 段2: 中层搁板薄板  link_1 Y: -0.0325 ~ -0.0169  世界Z: 0.665~0.680 -->
                <geom type="box" size="0.1807 0.0078 0.1807" pos="0.0091 -0.02457 0.0026"
                      condim="4" solimp="2 1 0.01" solref="0.01 1" friction="1 0.005 0.0001"
                      group="3" rgba="0 0 0 0" name="t22508_shelf_col"/>
                <!-- 段3: 上部桌面  link_1 Y: +0.104 ~ +0.198  世界Z: 0.801~0.895 -->
                <!-- 马克杯顶部在 link_1 Y≈+0.0871，此段从+0.104开始留出 16.9mm 间隙 -->
                <geom type="box" size="0.1911 0.0468 0.1911" pos="0.0104 0.1508 0.0039"
                      condim="4" solimp="2 1 0.01" solref="0.01 1" friction="1 0.005 0.0001"
                      group="3" rgba="0 0 0 0" name="t22508_top_col"/>
                <!-- link_0: 抽屉, range=[0, 0.2665m] (0.82m × 0.325) -->
                <body name="table_22508_drawer">
                    <joint name="table_22508_drawer_slide" type="slide" axis="0 0 1"
                           range="0 0.2665" damping="2" frictionloss="0.5"/>
                    <inertial pos="0.0091 -0.0767 0.0325" mass="0.6591"
                              diaginertia="0.00371293 0.00371293 0.00371293"/>
                    <geom type="mesh" mesh="t22508_drawer" material="t22508_wood"
                          contype="0" conaffinity="0" group="2" name="t22508_drawer_visual"/>
                    <geom type="box" size="0.1508 0.0442 0.1716" pos="0.0091 -0.0767 0.0325"
                          condim="4" solimp="2 1 0.01" solref="0.01 1" friction="1 0.005 0.0001"
                          group="3" rgba="0 0 0 0" name="t22508_drawer_col"/>
                </body>
            </body>
        </body>

        <geom name="tar_plane" pos="0.6 0.0 0.301" type="box" size="0.04 0.04 0.001" rgba="0 1 0 1"/>

        <!-- Side camera: fixed third-person view from upper-left of table (robot's perspective) -->
        <body name="side_camera_mount" pos="0 0 0">
            <camera name="side_camera" pos="0.85 0.35 0.80"
                    xyaxes="-0.574 0.819 0.000 -0.454 -0.318 0.832" fovy="60"/>
            <!-- Visual marker so the camera is visible in the viewer -->
            <geom name="side_cam_marker" pos="0.85 0.35 0.80"
                  type="box" size="0.04 0.04 0.025"
                  rgba="0.1 0.5 1.0 1.0" contype="0" conaffinity="0"/>
            <!-- Stick connecting camera to ground for easier spotting -->
            <geom name="side_cam_stick" pos="0.85 0.35 0.40"
                  type="cylinder" size="0.008 0.40"
                  rgba="0.1 0.5 1.0 0.5" contype="0" conaffinity="0"/></body>
    </worldbody>

    <include file="setting.xml"/>

    <keyframe>
        <!-- qpos: 8 robot + 7 mug + 7 table_22508_free + 1 drawer = 23 -->
        <!-- bodies: mug, table_22508(+drawer)  [apple/block/dog/kong/panda 已注释] -->
        <!-- ctrl: 7 actuators (6 arm + 1 gripper) -->
        <key name="home" qpos="
        0.0 0.0 0.0 0.0 0.0 0.0 0.0 0.0
        0.45 -0.018 0.6803 0.0 0.0 0.0 1.0
        0.58 -0.05 0.69685 1.0 0.0 0.0 0.0 0.0" ctrl="
        0.0 0.0 0.0 0.0 0.0 0.0 0.0"/>
    </keyframe>
</mujoco>
