<mujocoinclude>
    <body name="base_link">
        <inertial pos="-0.00081 0.00006 0.0568" mass="0.618" diaginertia="0.00056 0.00059 0.00061"/>
        <geom type="mesh" rgba="1 1 1 1" mesh="arm_base_link"/>

        <!-- link 1 -->
        <body name="link_1" pos="0 0 0.08355">
            <inertial pos="0.00884 -0.0004 0.0346" mass="0.296" diaginertia="0.00048 0.0003 0.00042"/>
            <joint name="joint_1" pos="0 0 0" axis="0 0 1" range="-2.8623 2.8623" limited="true" armature="0.01" damping="0.1" frictionloss="0.5"/>
            <geom type="mesh" rgba="0.92549 0.92549 0.92549 1" mesh="arm_link_1"/>

            <!-- link 2 -->
            <body name="link_2" pos="0.02 -0.0285 0.0555">
                <inertial pos="-0.0016 0.0274 0.1338" mass="1.344" diaginertia="0.0191 0.0189 0.00086"/>
                <joint name="joint_2" pos="0 0 0" axis="0 1 0" range="-2.0943 1.5707" limited="true" armature="0.01" damping="0.1" frictionloss="0.5"/>
                <geom type="mesh" rgba="1 1 1 1" mesh="arm_link_2"/>

                <!-- link 3 -->
                <body name="link_3" pos="0 0 0.27">
                    <inertial pos="-0.0545 0.0277 0.1463" mass="1.086" diaginertia="0.0117 0.0118 0.00148"/>
                    <joint name="joint_3" pos="0 0 0" axis="0 1 0" range="0 3.159" limited="true" armature="0.01" damping="0.1" frictionloss="0.5"/>
                    <geom type="mesh" rgba="1 1 1 1" mesh="arm_link_3"/>

                    <!-- link 4 -->
                    <body name="link_4" pos="-0.065 -0.00005 0.25">
                        <inertial pos="-0.0464 0.0283 0.0449" mass="0.535" diaginertia="0.00085 0.00109 0.00087"/>
                        <joint name="joint_4" pos="0 0 0" axis="0 1 0" range="-1.5707 1.5707" limited="true" armature="0.01" damping="0.02" frictionloss="0.1"/>
                        <geom type="mesh" rgba="0.792157 0.792157 0.792157 1" mesh="arm_link_4"/>

                        <!-- link 5 -->
                        <body name="link_5" pos="-0.046 0.0285 0.065">
                            <inertial pos="0.0408 0.00006 0.0072" mass="0.39" diaginertia="0.000165 0.00023 0.000217"/>
                            <joint name="joint_5" pos="0 0 0" axis="-1 0 0" range="-1.5707 1.5707" limited="true" armature="0.01" damping="0.02" frictionloss="0.1"/>
                            <geom type="mesh" rgba="0.898039 0.917647 0.929412 1" mesh="arm_link_5"/>

                            <!-- link 6 (wrist rotation) -->
                            <body name="link_6" pos="0.046 0 0.034">
                                <inertial pos="-0.0009 0.0001 0.0596" mass="0.676" diaginertia="0.0011 0.0011 0.0004"/>
                                <joint name="joint_6" pos="0 0 0" axis="0 0 1" range="-3.1415 3.1415" limited="true" armature="0.01" damping="0.02" frictionloss="0.1"/>
                                <geom type="mesh" rgba="0.898039 0.917647 0.929412 1" mesh="arm_link_6"/>

                                <!-- gripper base link (GP100) - rotated -90 deg around Y -->
                                <body name="gripper_base_link" pos="0 0 0" quat="0.7071068 0 -0.7071068 0">
                                    <inertial pos="0.0422 0 0.0116" mass="0.283" diaginertia="0.000242 0.000255 0.000177"/>
                                    <geom type="mesh" rgba="1 1 1 1" mesh="gripper_base_link"/>

                                    <!-- camera link -->
                                    <geom pos="0.0404 0 0.1201" type="mesh" rgba="0.667 0.698 0.769 1" mesh="camera_link"/>
                                    <camera name="end_camera" pos="0.066 0 0.105" quat="0.6123724 0.3535534 -0.3535534 -0.6123724" fovy="50"/>

                                    <!-- ee frame (TCP at 187mm from gripper base) -->
                                    <body name="ee_frame" pos="0.187 0.0 0.0" quat="1 0 0 0">
                                        <geom type="cylinder" size="0.002 0.01" pos="0.01 0.00 0.00" quat="0.7071068 0.0 0.7071068 0.0" rgba="1 0 0 1" contype="0" conaffinity="0" group="4"/>
                                        <geom type="cylinder" size="0.002 0.01" pos="0.00 0.01 0.00" quat="0.7071068 0.7071068 0.0 0.0" rgba="0 1 0 1" contype="0" conaffinity="0" group="4"/>
                                        <geom type="cylinder" size="0.002 0.01" pos="0.00 0.00 0.01" quat="1.0 0.0 0.0 0.0" rgba="0 0 1 1" contype="0" conaffinity="0" group="4"/>
                                    </body>

                                    <!-- left helper link (parallel linkage) - uses link_1.STL -->
                                    <body name="gripper_left_helper_link" pos="0.057667 0.030604 0.000025">
                                        <inertial pos="0.00299 0.02326 -0.00005" mass="0.00595" diaginertia="0.0000027 0.0000015 0.0000013"/>
                                        <joint name="gripper_left_helper_joint" pos="0 0 0" axis="0 0 -1" range="0 1.52" limited="true" armature="0.01" damping="1.0" frictionloss="0.1"/>
                                        <geom type="mesh" rgba="1 1 1 1" mesh="gripper_left_helper_link"/>
                                    </body>

                                    <!-- right helper link (parallel linkage) - uses link_4.STL -->
                                    <body name="gripper_right_helper_link" pos="0.057667 -0.030604 0.000025">
                                        <inertial pos="0.00299 -0.02326 -0.00005" mass="0.00595" diaginertia="0.0000027 0.0000015 0.0000013"/>
                                        <joint name="gripper_right_helper_joint" pos="0 0 0" axis="0 0 1" range="0 1.52" limited="true" armature="0.01" damping="1.0" frictionloss="0.1"/>
                                        <geom type="mesh" rgba="1 1 1 1" mesh="gripper_right_helper_link"/>
                                    </body>

                                    <!-- left gripper link 1 (driven) - uses link_2.STL -->
                                    <body name="gripper_left_link_1" pos="0.0721 0.014 0.000025">
                                        <inertial pos="0.00299 0.02326 -0.00005" mass="0.00595" diaginertia="0.0000027 0.0000015 0.0000013"/>
                                        <joint name="gripper_left_joint_1" pos="0 0 0" axis="0 0 -1" range="0 1.52" limited="true" armature="0.01" damping="1.0" frictionloss="0.1"/>
                                        <geom type="mesh" rgba="1 1 1 1" mesh="gripper_left_link_1"/>

                                        <!-- left gripper link 2 (fingertip) - uses link_3.STL -->
                                        <body name="gripper_left_link_2" pos="0.0085108 0.04927 0">
                                            <inertial pos="0.0255 0.00915 -0.00176" mass="0.0339" diaginertia="0.0000043 0.0000128 0.0000136"/>
                                            <joint name="gripper_left_joint_2" pos="0 0 0" axis="0 0 1" range="0 1.52" limited="true" armature="0.01" damping="1.0" frictionloss="0.1"/>
                                            <geom type="mesh" rgba="1 1 1 1" mesh="gripper_left_link_2"/>
                                        </body>
                                    </body>

                                    <!-- right gripper link 1 (driven) - uses link_5.STL -->
                                    <body name="gripper_right_link_1" pos="0.0721 -0.014 0.000025">
                                        <inertial pos="0.00299 -0.02326 -0.00005" mass="0.00595" diaginertia="0.0000027 0.0000015 0.0000013"/>
                                        <joint name="gripper_right_joint_1" pos="0 0 0" axis="0 0 1" range="0 1.52" limited="true" armature="0.01" damping="1.0" frictionloss="0.1"/>
                                        <geom type="mesh" rgba="1 1 1 1" mesh="gripper_right_link_1"/>

                                        <!-- right gripper link 2 (fingertip) - uses link_6.STL -->
                                        <body name="gripper_right_link_2" pos="0.0085108 -0.04927 0">
                                            <inertial pos="0.0255 -0.00915 -0.00176" mass="0.0339" diaginertia="0.0000043 0.0000128 0.0000136"/>
                                            <joint name="gripper_right_joint_2" pos="0 0 0" axis="0 0 -1" range="0 1.52" limited="true" armature="0.01" damping="1.0" frictionloss="0.1"/>
                                            <geom type="mesh" rgba="1 1 1 1" mesh="gripper_right_link_2"/>
                                        </body>
                                    </body>
                                </body>
                            </body>
                        </body>
                    </body>
                </body>
            </body>
        </body>
    </body>
</mujocoinclude>
